<?xml version="1.0" encoding="utf-8"?>
<!-- This URDF was automatically created by SolidWorks to URDF Exporter! Originally created by Stephen Brawner (brawner@gmail.com) 
     Commit Version: 1.5.1-0-g916b5db  Build Version: 1.5.7152.31018
     For more information, please see http://wiki.ros.org/sw_urdf_exporter -->
<robot
  name="ee_assem">
  <link
    name="base_link">
    <inertial>
      <origin
        xyz="8.3267E-17 0 0.096992"
        rpy="0 0 0" />
      <mass
        value="0.24537" />
      <inertia
        ixx="0.0006313"
        ixy="3.4792E-20"
        ixz="-5.4174E-19"
        iyy="0.00085607"
        iyz="4.6906E-20"
        izz="0.00041783" />
    </inertial>
    <visual>
      <origin
        xyz="0 0 0"
        rpy="0 0 0" />
      <geometry>
        <mesh
          filename="package://ee_assem/meshes/base_link.STL" />
      </geometry>
      <material
        name="">
        <color
          rgba="0.79216 0.81961 0.93333 1" />
      </material>
    </visual>
    <collision>
      <origin
        xyz="0 0 0"
        rpy="0 0 0" />
      <geometry>
        <mesh
          filename="package://ee_assem/meshes/base_link.STL" />
      </geometry>
    </collision>
  </link>
  <link
    name="link_1">
    <inertial>
      <origin
        xyz="-0.0065931 0 0.024057"
        rpy="0 0 0" />
      <mass
        value="0.0153" />
      <inertia
        ixx="4.711E-06"
        ixy="1.2925E-23"
        ixz="-3.3914E-07"
        iyy="4.494E-06"
        iyz="1.2925E-23"
        izz="7.6554E-07" />
    </inertial>
    <visual>
      <origin
        xyz="0 0 0"
        rpy="0 0 0" />
      <geometry>
        <mesh
          filename="package://ee_assem/meshes/link_1.STL" />
      </geometry>
      <material
        name="">
        <color
          rgba="0.79216 0.81961 0.93333 1" />
      </material>
    </visual>
    <collision>
      <origin
        xyz="0 0 0"
        rpy="0 0 0" />
      <geometry>
        <mesh
          filename="package://ee_assem/meshes/link_1.STL" />
      </geometry>
    </collision>
  </link>
  <joint
    name="joint_1"
    type="prismatic">
    <origin
      xyz="0 0 0.163"
      rpy="0 0 0" />
    <parent
      link="base_link" />
    <child
      link="link_1" />
    <axis
      xyz="-1 0 0" />
    <limit
      lower="-0.2"
      upper="0"
      effort="20"
      velocity="2" />
  </joint>
  <link
    name="link_2">
    <inertial>
      <origin
        xyz="-0.0065931 0 0.024057"
        rpy="0 0 0" />
      <mass
        value="0.0153" />
      <inertia
        ixx="4.711E-06"
        ixy="-4.4529E-24"
        ixz="-3.3914E-07"
        iyy="4.494E-06"
        iyz="1.0501E-22"
        izz="7.6554E-07" />
    </inertial>
    <visual>
      <origin
        xyz="0 0 0"
        rpy="0 0 0" />
      <geometry>
        <mesh
          filename="package://ee_assem/meshes/link_2.STL" />
      </geometry>
      <material
        name="">
        <color
          rgba="0.79216 0.81961 0.93333 1" />
      </material>
    </visual>
    <collision>
      <origin
        xyz="0 0 0"
        rpy="0 0 0" />
      <geometry>
        <mesh
          filename="package://ee_assem/meshes/link_2.STL" />
      </geometry>
    </collision>
  </link>
  <joint
    name="joint_2"
    type="prismatic">
    <origin
      xyz="0 0 0.163"
      rpy="0 0 3.1416" />
    <parent
      link="base_link" />
    <child
      link="link_2" />
    <axis
      xyz="1 0 0" />
    <limit
      lower="0"
      upper="0.2"
      effort="20"
      velocity="2" />
  </joint>
</robot>
